Workbook
Name lstFeatures: RoleMatrix!$D$5:$D$64
Name searchStringPrefix: UI!$R$3
Name temp: 'RoleMatrix-OLD'!$C$5:$K$46

Sheet Definitions
A2: # | B2: Term | C2: Description
A3: 1 | B3: Entity | C3: A logical unit/functionality
A4: 2 | B4: Verb | C4: Any logical activity that can be performed on an entity
A5: 3 | B5: Feature | C5: Concatenation of entity and verb
A9: # | B9: Verb | C9: Description | D9: Type
A10: 1 | B10: create | C10: Create an entity (logical) | D10: Standard
A11: 2 | B11: delete | C11: Delete an entity (logical) | D11: Standard
A12: 3 | B12: edit | C12: Edit an entity | D12: Standard
A13: 4 | B13: view | C13: View an entity | D13: Standard
A14: 5 | B14: list | C14: List a group of similar entities. E.g. list of cases, list of users, list of attributes across cases Note: List of attributes/attachments within a case is NOT considered "list" as it falls under "view" | D14: Standard
A15: 6 | B15: allow | C15: Indicates whether a feature is allowed (or not). E.g. Ability to be a owner/reviewer etc. of a case should not be allowed for all. | D15: Standard

Sheet RoleMatrix
G2: RoleTypeCde
G3: 101 | H3: 102 | I3: 103 | J3: 104 | K3: 105 | L3: Traceability
A4: # | B4: Entity | C4: Verb | D4: Feature | E4: Feature Description | F4: UI Implementation? | G4: admin | H4: agent | I4: manager | J4: guest | K4: service | L4: API - Hit Count | M4: UI - Hit Count | N4: Service - Hit Count | O4: Comments
A5: 1 | B5: core | C5: edit | D5: =B5 & "-" & C5 -> core-edit | E5: Mandatory features | F5: ?? | G5: 3 | H5: 3 | I5: 3 | J5: 3 | K5: 3 | L5: =COUNTIFS(APIs!F:F,D5) -> 2 | M5: =COUNTIFS(UI!F:F,D5) -> 0 | N5: =COUNTIFS(Service!D:D,D5) -> 0
A6: 2 | B6: core | C6: view | D6: =B6 & "-" & C6 -> core-view | E6: Mandatory features | F6: ?? | G6: 3 | H6: 3 | I6: 3 | J6: 3 | K6: 3 | L6: =COUNTIFS(APIs!F:F,D6) -> 4 | M6: =COUNTIFS(UI!F:F,D6) -> 2 | N6: =COUNTIFS(Service!D:D,D6) -> 0
A7: 3 | B7: action | C7: create | D7: =B7 & "-" & C7 -> action-create | E7: Create new action | F7: Yes | G7: 3 | H7: 3 | I7: 3 | K7: 3 | L7: =COUNTIFS(APIs!F:F,D7) -> 1 | M7: =COUNTIFS(UI!F:F,D7) -> 2 | N7: =COUNTIFS(Service!D:D,D7) -> 1
A8: 3a | B8: maker_action | C8: create | D8: =B8 & "-" & C8 -> maker_action-create | E8: Create new action by maker | F8: Yes | G8: 3 | H8: 3 | I8: 2 | K8: 3 | L8: =COUNTIFS(APIs!F:F,D8) -> 0 | M8: =COUNTIFS(UI!F:F,D8) -> 0 | N8: =COUNTIFS(Service!D:D,D8) -> 0 | O8: Mohan 01/16/2023 - Deleted
A9: 3b | B9: checker_action | C9: create | D9: =B9 & "-" & C9 -> checker_action-create | E9: Create new action by checker | F9: Yes | G9: 3 | H9: 2 | I9: 3 | K9: 3 | L9: =COUNTIFS(APIs!F:F,D9) -> 0 | M9: =COUNTIFS(UI!F:F,D9) -> 0 | N9: =COUNTIFS(Service!D:D,D9) -> 0 | O9: Mohan 01/16/2023 - Deleted
A10: 4 | B10: action | C10: delete | D10: =B10 & "-" & C10 -> action-delete | E10: Delete action | F10: No | G10: 3 | I10: 3 | L10: =COUNTIFS(APIs!F:F,D10) -> 1 | M10: =COUNTIFS(UI!F:F,D10) -> 0 | N10: =COUNTIFS(Service!D:D,D10) -> 0
A11: 5 | B11: action | C11: edit | D11: =B11 & "-" & C11 -> action-edit | E11: Edit action details | F11: No | G11: 3 | I11: 3 | K11: 3 | L11: =COUNTIFS(APIs!F:F,D11) -> 1 | M11: =COUNTIFS(UI!F:F,D11) -> 0 | N11: =COUNTIFS(Service!D:D,D11) -> 0
A12: 6 | B12: action | C12: list | D12: =B12 & "-" & C12 -> action-list | E12: View actions across cases | F12: No | G12: 3 | H12: 3 | I12: 3 | J12: 3 | K12: 3 | L12: =COUNTIFS(APIs!F:F,D12) -> 1 | M12: =COUNTIFS(UI!F:F,D12) -> 0 | N12: =COUNTIFS(Service!D:D,D12) -> 1
A13: 7 | B13: action | C13: view | D13: =B13 & "-" & C13 -> action-view | E13: View action(s) on case | F13: Yes | G13: 3 | H13: 3 | I13: 3 | J13: 3 | K13: 3 | L13: =COUNTIFS(APIs!F:F,D13) -> 4 | M13: =COUNTIFS(UI!F:F,D13) -> 2 | N13: =COUNTIFS(Service!D:D,D13) -> 2
A14: 7a | B14: action_data_entry_completed | C14: create | D14: =B14 & "-" & C14 -> action_data_entry_completed-create | E14: Create new special action - data entry completed | F14: Yes | G14: 3 | H14: 3 | I14: 1 | L14: =COUNTIFS(APIs!F:F,D14) -> 1 | M14: =COUNTIFS(UI!F:F,D14) -> 1 | N14: =COUNTIFS(Service!D:D,D14) -> 0 | O14: Mohan 01/16/2023 - Added
A15: 7b | B15: action_data_entry_approved | C15: create | D15: =B15 & "-" & C15 -> action_data_entry_approved-create | E15: Create new special action - data entry approved | F15: Yes | G15: 3 | H15: 1 | I15: 3 | L15: =COUNTIFS(APIs!F:F,D15) -> 1 | M15: =COUNTIFS(UI!F:F,D15) -> 1 | N15: =COUNTIFS(Service!D:D,D15) -> 0 | O15: Mohan 01/16/2023 - Added
A16: 7c | B16: action_data_entry_rejected | C16: create | D16: =B16 & "-" & C16 -> action_data_entry_rejected-create | E16: Create new special action - data entry rejected | F16: Yes | G16: 3 | H16: 1 | I16: 3 | L16: =COUNTIFS(APIs!F:F,D16) -> 1 | M16: =COUNTIFS(UI!F:F,D16) -> 1 | N16: =COUNTIFS(Service!D:D,D16) -> 0 | O16: Mohan 01/16/2023 - Added
A17: 8 | B17: attachment | C17: create | D17: =B17 & "-" & C17 -> attachment-create | E17: Create attachment | F17: No | G17: 3 | I17: 3 | K17: 3 | L17: =COUNTIFS(APIs!F:F,D17) -> 3 | M17: =COUNTIFS(UI!F:F,D17) -> 0 | N17: =COUNTIFS(Service!D:D,D17) -> 0
A18: 9 | B18: attachment | C18: view | D18: =B18 & "-" & C18 -> attachment-view | E18: View attachment on case | F18: Yes | G18: 3 | H18: 3 | I18: 3 | J18: 3 | L18: =COUNTIFS(APIs!F:F,D18) -> 2 | M18: =COUNTIFS(UI!F:F,D18) -> 2 | N18: =COUNTIFS(Service!D:D,D18) -> 2
A19: 10 | B19: attribute | C19: create | D19: =B19 & "-" & C19 -> attribute-create | E19: Create attribute on case | F19: Yes | G19: 3 | H19: 3 | I19: 3 | K19: 3 | L19: =COUNTIFS(APIs!F:F,D19) -> 3 | M19: =COUNTIFS(UI!F:F,D19) -> 2 | N19: =COUNTIFS(Service!D:D,D19) -> 1
A20: 10a | B20: attribute_annotation | C20: create | D20: =B20 & "-" & C20 -> attribute_annotation-create | E20: Create attribute annotation on case | F20: Yes | G20: 3 | H20: 3 | I20: 3 | K20: 3 | L20: =COUNTIFS(APIs!F:F,D20) -> 0 | M20: =COUNTIFS(UI!F:F,D20) -> 1 | N20: =COUNTIFS(Service!D:D,D20) -> 1
A21: 11 | B21: attribute | C21: delete | D21: =B21 & "-" & C21 -> attribute-delete | E21: Delete attribute on case | F21: Yes | G21: 3 | H21: 3 | I21: 3 | L21: =COUNTIFS(APIs!F:F,D21) -> 2 | M21: =COUNTIFS(UI!F:F,D21) -> 1 | N21: =COUNTIFS(Service!D:D,D21) -> 0
A22: 11a | B22: attribute_annotation | C22: delete | D22: =B22 & "-" & C22 -> attribute_annotation-delete | E22: Delete attribute annotation on case | F22: Yes | G22: 3 | H22: 3 | I22: 3 | L22: =COUNTIFS(APIs!F:F,D22) -> 0 | M22: =COUNTIFS(UI!F:F,D22) -> 1 | N22: =COUNTIFS(Service!D:D,D22) -> 1
A23: 12 | B23: attribute | C23: edit | D23: =B23 & "-" & C23 -> attribute-edit | E23: Edit attribute on case | F23: Yes | G23: 3 | H23: 3 | I23: 3 | L23: =COUNTIFS(APIs!F:F,D23) -> 2 | M23: =COUNTIFS(UI!F:F,D23) -> 1 | N23: =COUNTIFS(Service!D:D,D23) -> 0
A24: 13 | B24: attribute | C24: list | D24: =B24 & "-" & C24 -> attribute-list | E24: View attributes across cases | F24: No | G24: 3 | I24: 3 | L24: =COUNTIFS(APIs!F:F,D24) -> 1 | M24: =COUNTIFS(UI!F:F,D24) -> 0 | N24: =COUNTIFS(Service!D:D,D24) -> 0
A25: 14 | B25: attribute | C25: view | D25: =B25 & "-" & C25 -> attribute-view | E25: View attribute(s) on case | F25: Yes | G25: 3 | H25: 3 | I25: 3 | J25: 3 | K25: 3 | L25: =COUNTIFS(APIs!F:F,D25) -> 8 | M25: =COUNTIFS(UI!F:F,D25) -> 1 | N25: =COUNTIFS(Service!D:D,D25) -> 1
A26: 14a | B26: attribute_annotation | C26: view | D26: =B26 & "-" & C26 -> attribute_annotation-view | E26: View attribute annotation(s) on case | F26: Yes | G26: 3 | H26: 3 | I26: 3 | J26: 3 | K26: 3 | L26: =COUNTIFS(APIs!F:F,D26) -> 0 | M26: =COUNTIFS(UI!F:F,D26) -> 1 | N26: =COUNTIFS(Service!D:D,D26) -> 1
A27: 14b | B27: attribute_source | C27: view | D27: =B27 & "-" & C27 -> attribute_source-view | E27: View attribute source on case | F27: Yes | G27: 3 | H27: 3 | I27: 3 | J27: 3 | K27: 3 | L27: =COUNTIFS(APIs!F:F,D27) -> 0 | M27: =COUNTIFS(UI!F:F,D27) -> 1 | N27: =COUNTIFS(Service!D:D,D27) -> 1
A28: 14c | B28: attribute_extractionpath | C28: view | D28: =B28 & "-" & C28 -> attribute_extractionpath-view | E28: View attribute extractionpath on case | F28: Yes | G28: 3 | H28: 3 | I28: 3 | J28: 3 | K28: 3 | L28: =COUNTIFS(APIs!F:F,D28) -> 0 | M28: =COUNTIFS(UI!F:F,D28) -> 2 | N28: =COUNTIFS(Service!D:D,D28) -> 1
A29: 15 | B29: audit_case | C29: create | D29: =B29 & "-" & C29 -> audit_case-create | E29: Add entry to case history | F29: No | G29: 3 | K29: 3 | L29: =COUNTIFS(APIs!F:F,D29) -> 1 | M29: =COUNTIFS(UI!F:F,D29) -> 0 | N29: =COUNTIFS(Service!D:D,D29) -> 0
A30: 16 | B30: audit_case | C30: view | D30: =B30 & "-" & C30 -> audit_case-view | E30: View case history | F30: Yes | G30: 3 | H30: 3 | I30: 3 | J30: 3 | L30: =COUNTIFS(APIs!F:F,D30) -> 2 | M30: =COUNTIFS(UI!F:F,D30) -> 1 | N30: =COUNTIFS(Service!D:D,D30) -> 0
A31: 16a | B31: audit_rbac | C31: view | D31: =B31 & "-" & C31 -> audit_rbac-view | E31: View app variable -RBAC history | F31: Yes | G31: 3 | I31: 3 | L31: =COUNTIFS(APIs!F:F,D31) -> 1 | M31: =COUNTIFS(UI!F:F,D31) -> 1 | N31: =COUNTIFS(Service!D:D,D31) -> 0
A32: 17 | B32: audit_user | C32: view | D32: =B32 & "-" & C32 -> audit_user-view | E32: View user history | F32: Yes | G32: 3 | L32: =COUNTIFS(APIs!F:F,D32) -> 1 | M32: =COUNTIFS(UI!F:F,D32) -> 1 | N32: =COUNTIFS(Service!D:D,D32) -> 0
A33: 18 | B33: close_case | C33: edit | D33: =B33 & "-" & C33 -> close_case-edit | E33: Close case | F33: Yes | G33: 3 | I33: 3 | K33: 3 | L33: =COUNTIFS(APIs!F:F,D33) -> 1 | M33: =COUNTIFS(UI!F:F,D33) -> 2 | N33: =COUNTIFS(Service!D:D,D33) -> 1
A34: 19 | B34: case | C34: create | D34: =B34 & "-" & C34 -> case-create | E34: Create case | F34: No | G34: 3 | K34: 3 | L34: =COUNTIFS(APIs!F:F,D34) -> 1 | M34: =COUNTIFS(UI!F:F,D34) -> 0 | N34: =COUNTIFS(Service!D:D,D34) -> 0
A35: 20 | B35: case | C35: delete | D35: =B35 & "-" & C35 -> case-delete | E35: Delete case | F35: No | G35: 3 | I35: 3 | L35: =COUNTIFS(APIs!F:F,D35) -> 1 | M35: =COUNTIFS(UI!F:F,D35) -> 0 | N35: =COUNTIFS(Service!D:D,D35) -> 0
A36: 21 | B36: case | C36: edit | D36: =B36 & "-" & C36 -> case-edit | E36: Edit case | F36: No | G36: 3 | H36: 3 | K36: 3 | L36: =COUNTIFS(APIs!F:F,D36) -> 2 | M36: =COUNTIFS(UI!F:F,D36) -> 0 | N36: =COUNTIFS(Service!D:D,D36) -> 1
A37: 22 | B37: case | C37: list | D37: =B37 & "-" & C37 -> case-list | E37: View case list | F37: Yes | G37: 3 | H37: 3 | I37: 3 | J37: 3 | K37: 3 | L37: =COUNTIFS(APIs!F:F,D37) -> 1 | M37: =COUNTIFS(UI!F:F,D37) -> 1 | N37: =COUNTIFS(Service!D:D,D37) -> 1
A38: 23 | B38: case-user | C38: create | D38: =B38 & "-" & C38 -> case-user-create | E38: Assign (unassigned) case (to self) | F38: Yes | G38: 3 | H38: 3 | I38: 3 | K38: 3 | L38: =COUNTIFS(APIs!F:F,D38) -> 1 | M38: =COUNTIFS(UI!F:F,D38) -> 2 | N38: =COUNTIFS(Service!D:D,D38) -> 1
A39: 24 | B39: case-user | C39: edit | D39: =B39 & "-" & C39 -> case-user-edit | E39: Assign (assigned) case to someone else | F39: Yes | G39: 3 | H39: 3 | I39: 3 | K39: 3 | L39: =COUNTIFS(APIs!F:F,D39) -> 2 | M39: =COUNTIFS(UI!F:F,D39) -> 2 | N39: =COUNTIFS(Service!D:D,D39) -> 0
A40: 24a | B40: case-user | C40: allow | D40: =B40 & "-" & C40 -> case-user-allow | E40: Required for a user to be a owner of a case | F40: Yes | G40: 3 | H40: 3 | I40: 3 | L40: =COUNTIFS(APIs!F:F,D40) -> 0 | M40: =COUNTIFS(UI!F:F,D40) -> 0 | N40: =COUNTIFS(Service!D:D,D40) -> 0 | O40: Mohan 01/16/2023 - Added
A41: 25 | B41: outbound_email | C41: create | D41: =B41 & "-" & C41 -> outbound_email-create | E41: Create outbound email | F41: Yes | G41: 3 | H41: 3 | I41: 3 | K41: 3 | L41: =COUNTIFS(APIs!F:F,D41) -> 2 | M41: =COUNTIFS(UI!F:F,D41) -> 2 | N41: =COUNTIFS(Service!D:D,D41) -> 0
...

Sheet APIs
A1: S No. | B1: Controller | C1: API | D1: Method | E1: Description | F1: Feature | G1: STATUS | H1: Type of Change | I1: Feature Validation | J1: API unique Validation | K1: Comments
A2: 1 | B2: about | C2: /api/v1/about | D2: GET | E2: Get details about the product | F2: core-view | G2: Same | H2: Config | I2: =IF(ISNA( VLOOKUP(F2,lstFeatures,1,FALSE)),"Invalid","Valid") -> Valid | J2: =C2&"-"&D2 -> /api/v1/about-GET
A3: 2 | B3: action | C3: /api/v1/action | D3: GET | E3: Get list of actions along with details | F3: action-list | G3: Same | H3: Code | I3: =IF(ISNA( VLOOKUP(F3,lstFeatures,1,FALSE)),"Invalid","Valid") -> Valid | J3: =C3&"-"&D3 -> /api/v1/action-GET
A4: 3 | B4: action | C4: /api/v1/action?docId=1000742 | D4: GET | E4: Get list of actions along with details for a given docId | F4: action-view | H4: Code | I4: =IF(ISNA( VLOOKUP(F4,lstFeatures,1,FALSE)),"Invalid","Valid") -> Valid | J4: =C4&"-"&D4 -> /api/v1/action?docId=1000742-GET
A5: 4 | B5: action | C5: /api/v1/action | D5: POST | E5: Add new action to document | F5: action-create | G5: Same | H5: Config | I5: =IF(ISNA( VLOOKUP(F5,lstFeatures,1,FALSE)),"Invalid","Valid") -> Valid | J5: =C5&"-"&D5 -> /api/v1/action-POST
A6: 5 | B6: action | C6: /api/v1/action | D6: PUT | E6: Update action status | F6: action-edit | G6: Same | H6: Config | I6: =IF(ISNA( VLOOKUP(F6,lstFeatures,1,FALSE)),"Invalid","Valid") -> Valid | J6: =C6&"-"&D6 -> /api/v1/action-PUT
A7: 6 | B7: action | C7: /api/v1/action/{docActionRelId} | D7: DELETE | E7: Delete an action | F7: action-delete | G7: Same | H7: Config | I7: =IF(ISNA( VLOOKUP(F7,lstFeatures,1,FALSE)),"Invalid","Valid") -> Valid | J7: =C7&"-"&D7 -> /api/v1/action/{docActionRelId}-DELETE
A8: 7 | B8: action | C8: /api/v1/action/mapping | D8: GET | E8: Returns mapping details of action's parameters with document's attributes | F8: action-view | G8: modified description | H8: Config | I8: =IF(ISNA( VLOOKUP(F8,lstFeatures,1,FALSE)),"Invalid","Valid") -> Valid | J8: =C8&"-"&D8 -> /api/v1/action/mapping-GET
A9: 8 | B9: action | C9: /api/v1/action/recommendation | D9: GET | E9: Get recommended action based on business rules configured | F9: action-view | G9: Added | H9: Config | I9: =IF(ISNA( VLOOKUP(F9,lstFeatures,1,FALSE)),"Invalid","Valid") -> Valid | J9: =C9&"-"&D9 -> /api/v1/action/recommendation-GET
A10: 9 | B10: action | C10: /api/v1/action/param/attr/recommendation | D10: GET | E10: Get data for mapping details of action's parameters with document's attributes | F10: action-view | G10: Added | H10: Config | I10: =IF(ISNA( VLOOKUP(F10,lstFeatures,1,FALSE)),"Invalid","Valid") -> Valid | J10: =C10&"-"&D10 -> /api/v1/action/param/attr/recommendation-GET
A11: 10 | B11: attachment | C11: /api/v1/attachment/doc | D11: GET | E11: Get list of attachments associated with docId | F11: attachment-view | G11: Modified | H11: Config | I11: =IF(ISNA( VLOOKUP(F11,lstFeatures,1,FALSE)),"Invalid","Valid") -> Valid | J11: =C11&"-"&D11 -> /api/v1/attachment/doc-GET
A12: 11 | B12: attachment | C12: /api/v1/attachment/doc | D12: POST | E12: Add a new attachment along with associated data | F12: attachment-create | G12: Modified | H12: Config | I12: =IF(ISNA( VLOOKUP(F12,lstFeatures,1,FALSE)),"Invalid","Valid") -> Valid | J12: =C12&"-"&D12 -> /api/v1/attachment/doc-POST
A13: 12 | B13: attachment | C13: /api/v1/attachment/doc/file | D13: GET | E13: Get attachment file for a given document id & attachment id | F13: attachment-view | G13: Modified | H13: Config | I13: =IF(ISNA( VLOOKUP(F13,lstFeatures,1,FALSE)),"Invalid","Valid") -> Valid | J13: =C13&"-"&D13 -> /api/v1/attachment/doc/file-GET
A14: 13 | B14: attachment | C14: /api/v1/attachment/doc/group | D14: POST | E14: Add a new attachment along with associated data to a group | F14: attachment-create | G14: Added | H14: Config | I14: =IF(ISNA( VLOOKUP(F14,lstFeatures,1,FALSE)),"Invalid","Valid") -> Valid | J14: =C14&"-"&D14 -> /api/v1/attachment/doc/group-POST
A15: 14 | B15: attachment | C15: /api/v1/attachment/email | D15: GET | E15: Get list of attachments associated with email outbound id | F15: outbound_email-view | G15: Added | H15: Config | I15: =IF(ISNA( VLOOKUP(F15,lstFeatures,1,FALSE)),"Invalid","Valid") -> Valid | J15: =C15&"-"&D15 -> /api/v1/attachment/email-GET
A16: 15 | B16: attachment | C16: /api/v1/attachment/email/file | D16: GET | E16: Get attachment file for a given email outbound id and attachment id | F16: outbound_email-view | G16: Added | H16: Config | I16: =IF(ISNA( VLOOKUP(F16,lstFeatures,1,FALSE)),"Invalid","Valid") -> Valid | J16: =C16&"-"&D16 -> /api/v1/attachment/email/file-GET
A17: 15a | B17: attachment | C17: /api/v1/attachment/attachment | D17: POST | E17: Add parent-child relationship records between two attachments | F17: attachment-create | G17: Added | H17: Config | I17: =IF(ISNA( VLOOKUP(F17,lstFeatures,1,FALSE)),"Invalid","Valid") -> Valid | J17: =C17&"-"&D17 -> /api/v1/attachment/attachment-POST
A18: 16 | B18: attribute | C18: /api/v1/attribute/edit | D18: POST | E18: Update one or more attributes | F18: attribute-edit | G18: Added | H18: Config | I18: =IF(ISNA( VLOOKUP(F18,lstFeatures,1,FALSE)),"Invalid","Valid") -> Valid | J18: =C18&"-"&D18 -> /api/v1/attribute/edit-POST
A19: 17 | B19: attribute | C19: /api/v1/attribute/attachment | D19: GET | E19: Get list of all (attachment) attribute(s) using docId or selected ones using [docId+attachmentId in CSV] | F19: attribute-view | G19: Added | H19: Config | I19: =IF(ISNA( VLOOKUP(F19,lstFeatures,1,FALSE)),"Invalid","Valid") -> Valid | J19: =C19&"-"&D19 -> /api/v1/attribute/attachment-GET
A20: 18 | B20: attribute | C20: /api/v1/attribute/values | D20: GET | E20: Get list of allowed value(s) for attribute(s), if configured | F20: attribute-view | G20: Added | H20: Config | I20: =IF(ISNA( VLOOKUP(F20,lstFeatures,1,FALSE)),"Invalid","Valid") -> Valid | J20: =C20&"-"&D20 -> /api/v1/attribute/values-GET
A21: 19 | B21: attribute | C21: /api/v1/attribute/notification | D21: GET | E21: Get notifications for attribute(s) based on business rules configured | F21: attribute-view | G21: Added | H21: Config | I21: =IF(ISNA( VLOOKUP(F21,lstFeatures,1,FALSE)),"Invalid","Valid") -> Valid | J21: =C21&"-"&D21 -> /api/v1/attribute/notification-GET
A22: 20 | B22: attribute | C22: /api/v1/attribute/export | D22: GET | E22: Export list of all (document and attachment) attributes | F22: attribute-view | G22: Added | H22: Config | I22: =IF(ISNA( VLOOKUP(F22,lstFeatures,1,FALSE)),"Invalid","Valid") -> Valid | J22: =C22&"-"&D22 -> /api/v1/attribute/export-GET
A23: 21 | B23: attribute | C23: /api/v1/attribute/document | D23: GET | E23: Get list of all (document) attributes | F23: attribute-view | G23: Added | H23: Config | I23: =IF(ISNA( VLOOKUP(F23,lstFeatures,1,FALSE)),"Invalid","Valid") -> Valid | J23: =C23&"-"&D23 -> /api/v1/attribute/document-GET
A24: 22 | B24: attribute | C24: /api/v1/attribute/sortkey | D24: GET | E24: Get sort key for attributes | F24: attribute-view | G24: Added | H24: Config | I24: =IF(ISNA( VLOOKUP(F24,lstFeatures,1,FALSE)),"Invalid","Valid") -> Valid | J24: =C24&"-"&D24 -> /api/v1/attribute/sortkey-GET
A25: 23 | B25: attribute | C25: /api/v1/attribute/attribute/mapping | D25: GET | E25: Get list of all attribute-to-attribute mapping | F25: attribute-view | G25: Added | H25: Config | I25: =IF(ISNA( VLOOKUP(F25,lstFeatures,1,FALSE)),"Invalid","Valid") -> Valid | J25: =C25&"-"&D25 -> /api/v1/attribute/attribute/mapping-GET
A26: 24 | B26: attribute | C26: /api/v1/attribute/names | D26: GET | E26: Get list of all attribute name(s), if configured | F26: attribute-view | G26: Added | H26: Config | I26: =IF(ISNA( VLOOKUP(F26,lstFeatures,1,FALSE)),"Invalid","Valid") -> Valid | J26: =C26&"-"&D26 -> /api/v1/attribute/names-GET
A27: 25 | B27: attribute | C27: /api/v1/attribute/delete | D27: POST | E27: Delete one or more attributes | F27: attribute-delete | G27: Added | H27: Config | I27: =IF(ISNA( VLOOKUP(F27,lstFeatures,1,FALSE)),"Invalid","Valid") -> Valid | J27: =C27&"-"&D27 -> /api/v1/attribute/delete-POST
A28: 26 | B28: attribute | C28: /api/v1/attribute/add | D28: POST | E28: Add one or more attributes | F28: attribute-create | G28: Added | H28: Config | I28: =IF(ISNA( VLOOKUP(F28,lstFeatures,1,FALSE)),"Invalid","Valid") -> Valid | J28: =C28&"-"&D28 -> /api/v1/attribute/add-POST
A29: 27 | B29: annotation | C29: /api/v1/annotation/add | D29: POST | E29: Add one or more annotations | F29: attribute-create | G29: Added | H29: Config | I29: =IF(ISNA( VLOOKUP(F29,lstFeatures,1,FALSE)),"Invalid","Valid") -> Valid | J29: =C29&"-"&D29 -> /api/v1/annotation/add-POST
... A31: 29 | B31: multiattribute | C31: /api/v1/multiattribute/manage | D31: POST | E31: Add/update/delete multi-attribute at document/attachment level | F31: attribute-create | G31: Added | H31: Code | I31: =IF(ISNA( VLOOKUP(F31,lstFeatures,1,FALSE)),"Invalid","Valid") -> Valid | J31: =C31&"-"&D31 -> /api/v1/multiattribute/manage-POST
A32: 30 | B32: multiattribute | C32: /api/v1/multiattribute/manage | D32: POST | E32: Add/update/delete multi-attribute at document/attachment level | F32: attribute-edit | H32: Code | I32: =IF(ISNA( VLOOKUP(F32,lstFeatures,1,FALSE)),"Invalid","Valid") -> Valid | J32: =C32&"-"&D32 -> /api/v1/multiattribute/manage-POST
A33: 31 | B33: multiattribute | C33: /api/v1/multiattribute/manage | D33: POST | E33: Add/update/delete multi-attribute at document/attachment level | F33: attribute-delete | H33: Code | I33: =IF(ISNA( VLOOKUP(F33,lstFeatures,1,FALSE)),"Invalid","Valid") -> Valid | J33: =C33&"-"&D33 -> /api/v1/multiattribute/manage-POST
A34: 32 | B34: audit | C34: /api/v1/audit/document | D34: GET | E34: Get audit details | F34: audit_case-view | G34: Added | H34: Config | I34: =IF(ISNA( VLOOKUP(F34,lstFeatures,1,FALSE)),"Invalid","Valid") -> Valid | J34: =C34&"-"&D34 -> /api/v1/audit/document-GET
A35: 33 | B35: audit | C35: /api/v1/audit/document | D35: POST | E35: Add audit details at case level | F35: audit_case-create | G35: Added | H35: Config | I35: =IF(ISNA( VLOOKUP(F35,lstFeatures,1,FALSE)),"Invalid","Valid") -> Valid | J35: =C35&"-"&D35 -> /api/v1/audit/document-POST
A36: 34 | B36: audit | C36: /api/v1/audit/user | D36: GET | E36: Get audit details | F36: audit_user-view | G36: Added | H36: Config | I36: =IF(ISNA( VLOOKUP(F36,lstFeatures,1,FALSE)),"Invalid","Valid") -> Valid | J36: =C36&"-"&D36 -> /api/v1/audit/user-GET
A37: 34a | B37: audit | C37: /api/v1/audit/variable | D37: GET | E37: Get app variable audit details | F37: audit_rbac-view | G37: New feature | H37: Config | I37: =IF(ISNA( VLOOKUP(F37,lstFeatures,1,FALSE)),"Invalid","Valid") -> Valid | J37: =C37&"-"&D37 -> /api/v1/audit/variable-GET
A38: 34b | B38: audit | C38: /api/v1/audit/document/currentuser | D38: GET | E38: Get case level audit history of currently logged in user | F38: audit_case-view | G38: Added (Dashboard) | H38: Config | I38: =IF(ISNA( VLOOKUP(F38,lstFeatures,1,FALSE)),"Invalid","Valid") -> Valid | J38: =C38&"-"&D38 -> /api/v1/audit/document/currentuser-GET
A39: 35 | B39: auth | C39: /api/v1/auth | D39: POST | E39: Get authorization token | F39: core-view | G39: Same | H39: Config | I39: =IF(ISNA( VLOOKUP(F39,lstFeatures,1,FALSE)),"Invalid","Valid") -> Valid | J39: =C39&"-"&D39 -> /api/v1/auth-POST
A40: 36 | B40: document | C40: /api/v1/document | D40: GET | E40: Get a list of documents with or without filter | F40: case-list | G40: Same | H40: Config | I40: =IF(ISNA( VLOOKUP(F40,lstFeatures,1,FALSE)),"Invalid","Valid") -> Valid | J40: =C40&"-"&D40 -> /api/v1/document-GET
A41: 37 | B41: document | C41: /api/v1/document | D41: POST | E41: Add a new document along with associated data | F41: case-create | G41: Same | H41: Config | I41: =IF(ISNA( VLOOKUP(F41,lstFeatures,1,FALSE)),"Invalid","Valid") -> Valid | J41: =C41&"-"&D41 -> /api/v1/document-POST
...

Sheet UI
E1: Note: Status is based on changes upto changeset # 18257
A3: S No. | B3: Page Name | C3: Page Element Name | D3: Page Element Type | E3: Capability | F3: Feature | G3: Comment | H3: Page URL | I3: User | J3: Traceability | K3: Status | L3: Status-Comment
A4: 1 | B4: Login | C4: All | D4: All | E4: User login | F4: core-view | H4: http://vainpdblr15:8080/docwb/ | I4: john | J4: =VLOOKUP(F4,lstFeatures,1,FALSE) -> core-view | K4: Done | L4: Verify if reqd
A5: 2 | B5: User Registration | C5: All | D5: All | E5: User registration | F5: core-view | H5: http://vainpdblr15:8080/docwb/#/registration | I5: john | J5: =VLOOKUP(F5,lstFeatures,1,FALSE) -> core-view | K5: Done | L5: Verify if reqd
A6: 3 | B6: Home | Configuration | Manage Users | C6: User List | D6: Table | E6: View user list and access details | F6: user-list | H6: http://vainpdblr15:8080/docwb/#/home/configuration/userlist | I6: admin | J6: =VLOOKUP(F6,lstFeatures,1,FALSE) -> user-list | K6: Done
A7: 4 | B7: Home | Configuration | Manage Users | C7: Enabled | D7: Checkbox | E7: Enable/Disable a user | F7: user-edit | H7: http://vainpdblr15:8080/docwb/#/home/configuration/userlist | I7: admin | J7: =VLOOKUP(F7,lstFeatures,1,FALSE) -> user-edit | K7: Done
A8: 5 | B8: Home | Configuration | Manage Users | C8: Role | D8: Dropdown | E8: Change the role of user | F8: user-edit | H8: http://vainpdblr15:8080/docwb/#/home/configuration/userlist | I8: admin | J8: =VLOOKUP(F8,lstFeatures,1,FALSE) -> user-edit | K8: Done
A9: 6 | B9: Home | Configuration | Manage Users | C9: Queue | D9: Checkbox | E9: Provide access to queue for selected user | F9: user-edit | H9: http://vainpdblr15:8080/docwb/#/home/configuration/userlist | I9: admin | J9: =VLOOKUP(F9,lstFeatures,1,FALSE) -> user-edit | K9: Done
A10: 7 | B10: Home | Configuration | Manage Users | C10: User History | D10: Button | E10: View user history details | F10: audit_user-view | H10: http://vainpdblr15:8080/docwb/#/home/configuration/userlist | I10: admin | J10: =VLOOKUP(F10,lstFeatures,1,FALSE) -> audit_user-view | K10: Done
A11: 8 | B11: Home | Configuration | Manage Users | C11: Save | D11: Button | E11: Save user details | F11: user-edit | H11: http://vainpdblr15:8080/docwb/#/home/configuration/userlist | I11: admin | J11: =VLOOKUP(F11,lstFeatures,1,FALSE) -> user-edit | K11: Done
A12: 8a | B12: Home | Configuration | Manage RBAC | C12: RBAC | D12: Table | E12: View RBAC configuration | F12: rbac-view | G12: Refresh button also | H12: http://vainpdblr15:8080/docwb/#/home/configuration/rbac | I12: admin | J12: =VLOOKUP(F12,lstFeatures,1,FALSE) -> rbac-view | K12: Done
A13: 8b | B13: Home | Configuration | Manage RBAC | C13: Save | D13: Button | E13: Save RBAC configuration updates | F13: rbac-edit | G13: Cancel button also | H13: http://vainpdblr15:8080/docwb/#/home/configuration/rbac | I13: admin | J13: =VLOOKUP(F13,lstFeatures,1,FALSE) -> rbac-edit | K13: Done
A14: 8c | B14: Home | Configuration | Manage RBAC | C14: RBAC History | D14: Button | E14: View RBAC history details | F14: audit_rbac-view | H14: http://vainpdblr15:8080/docwb/#/home/configuration/rbac | I14: admin | J14: =VLOOKUP(F14,lstFeatures,1,FALSE) -> audit_rbac-view | K14: Done
A15: 9 | B15: Home | C15: My Queues | D15: Tree Menu | E15: View queues | F15: queue-list | H15: http://vainpdblr15:8080/docwb/#/home/myqueues | I15: john | J15: =VLOOKUP(F15,lstFeatures,1,FALSE) -> queue-list | K15: Done
A16: 10 | B16: Home | My Queues | <Queue Name> | <Case Status> | C16: <Case List> | D16: Table | E16: View list of cases | F16: case-list | H16: http://vainpdblr15:8080/docwb/#/home/worklist/11/100 | I16: john | J16: =VLOOKUP(F16,lstFeatures,1,FALSE) -> case-list | K16: Done
A17: 11 | B17: Home | My Queues | <Queue Name> | <Case Status> | C17: Assign To Me | D17: Link | E17: Assign case to self from unassigned in NEW | F17: case-user-create | H17: http://vainpdblr15:8080/docwb/#/home/worklist/11/100 | I17: john | J17: =VLOOKUP(F17,lstFeatures,1,FALSE) -> case-user-create | K17: Done
A18: 12 | B18: Home | My Queues | <Queue Name> | <Case Status> | C18: Reassign | D18: Button | E18: Reassign case to someone else | F18: case-user-edit | H18: http://vainpdblr15:8080/docwb/#/home/worklist/11/200 | I18: john | J18: =VLOOKUP(F18,lstFeatures,1,FALSE) -> case-user-edit | K18: Done
A19: 13 | B19: Home | My Queues | <Queue Name> | <Case Status> | C19: Close | D19: Button | E19: Closes a case | F19: close_case-edit | H19: http://vainpdblr15:8080/docwb/#/home/worklist/11/200 | I19: john | J19: =VLOOKUP(F19,lstFeatures,1,FALSE) -> close_case-edit | K19: Done
A20: 14 | B20: Home | My Queues | <Queue Name> | Case ### | C20: <document name> | D20: Tab | E20: View attachment(s) on case | F20: attachment-view | H20: http://vainpdblr15:8080/docwb/#/home/workdata/11/1014334 | I20: john | J20: =VLOOKUP(F20,lstFeatures,1,FALSE) -> attachment-view | K20: Done
A21: 15 | B21: Home | My Queues | <Queue Name> | Case ### | C21: Download | D21: Icon | E21: Download attachment(s) on case | F21: attachment-view | H21: http://vainpdblr15:8080/docwb/#/home/workdata/11/1014334 | I21: john | J21: =VLOOKUP(F21,lstFeatures,1,FALSE) -> attachment-view | K21: Done
A22: 16 | B22: Home | My Queues | <Queue Name> | Case ### | C22: Annotations | D22: Toggle | E22: View annotations on case | F22: attribute_annotation-view | H22: http://vainpdblr15:8080/docwb/#/home/workdata/11/1001861 | I22: john | J22: =VLOOKUP(F22,lstFeatures,1,FALSE) -> attribute_annotation-view | K22: Done
A23: 16b | B23: Home | My Queues | <Queue Name> | Case ### | C23: Annotations | D23: Button | E23: LHS delete annotations on case | F23: attribute_annotation-delete | H23: http://vainpdblr15:8080/docwb/#/home/workdata/11/1001861 | I23: john | J23: =VLOOKUP(F23,lstFeatures,1,FALSE) -> attribute_annotation-delete | K23: Done
A24: 16c | B24: Home | My Queues | <Queue Name> | Case ### | C24: Annotations | D24: Button | E24: LHS add annotations on case | F24: attribute_annotation-create | H24: http://vainpdblr15:8080/docwb/#/home/workdata/11/1001861 | I24: john | J24: =VLOOKUP(F24,lstFeatures,1,FALSE) -> attribute_annotation-create | K24: Done
A25: 17 | B25: Home | My Queues | <Queue Name> | Case ### | C25: Assign To Me | D25: Button | E25: Assign case to self from unassigned in NEW | F25: case-user-create | H25: http://vainpdblr15:8080/docwb/#/home/workdata/11/1001861 | I25: john | J25: =VLOOKUP(F25,lstFeatures,1,FALSE) -> case-user-create | K25: Done
A26: 18 | B26: Home | My Queues | <Queue Name> | Case ### | C26: Reassign | D26: Button | E26: Reassign case to someone else | F26: case-user-edit | H26: http://vainpdblr15:8080/docwb/#/home/workdata/11/1001861 | I26: john | J26: =VLOOKUP(F26,lstFeatures,1,FALSE) -> case-user-edit | K26: Done
A27: 19 | B27: Home | My Queues | <Queue Name> | Case ### | C27: Extracted Data | D27: Table | E27: View attributes on case | F27: attribute-view | H27: http://vainpdblr15:8080/docwb/#/home/workdata/11/1001844 | I27: john | J27: =VLOOKUP(F27,lstFeatures,1,FALSE) -> attribute-view | K27: Done
A28: 19a | B28: Home | My Queues | <Queue Name> | Case ### | C28: Extracted Data | D28: Table | E28: View attributes source on case | F28: attribute_source-view | H28: http://vainpdblr15:8080/docwb/#/home/workdata/11/1001844 | I28: john | J28: =VLOOKUP(F28,lstFeatures,1,FALSE) -> attribute_source-view | K28: Done
A29: 19b | B29: Home | My Queues | <Queue Name> | Case ### | C29: Extraction Path | D29: Icon | E29: View attributes source on case | F29: attribute_extractionpath-view | H29: http://vainpdblr15:8080/docwb/#/home/workdata/11/1001844 | I29: john | J29: =VLOOKUP(F29,lstFeatures,1,FALSE) -> attribute_extractionpath-view | K29: Done
A30: 19c | B30: Home | My Queues | <Queue Name> | Case ### | Extraction Path attachmentId | C30: Extraction Path | D30: Table | E30: View attributes source on case | F30: attribute_extractionpath-view | H30: http://vainpdblr15:8080/docwb/#/home/workdata/11/1001844/extractionpath/2323 | I30: john | J30: =VLOOKUP(F30,lstFeatures,1,FALSE) -> attribute_extractionpath-view | K30: Done
A31: 20 | B31: Home | My Queues | <Queue Name> | Case ### | C31: Add | D31: Icon | E31: Add new attribute on a case | F31: attribute-create | H31: http://vainpdblr15:8080/docwb/#/home/workdata/11/1001844 | I31: john | J31: =VLOOKUP(F31,lstFeatures,1,FALSE) -> attribute-create | K31: Done
A32: 21 | B32: Home | My Queues | <Queue Name> | Case ### | C32: Delete | D32: Icon | E32: Delete existing attributes on case | F32: attribute-delete | H32: http://vainpdblr15:8080/docwb/#/home/workdata/11/1001844 | I32: john | J32: =VLOOKUP(F32,lstFeatures,1,FALSE) -> attribute-delete | K32: Done
A33: 22 | B33: Home | My Queues | <Queue Name> | Case ### | C33: <None> | D33: Textbox | E33: Edit existing attributes on case | F33: attribute-edit | H33: http://vainpdblr15:8080/docwb/#/home/workdata/11/1001844 | I33: john | J33: =VLOOKUP(F33,lstFeatures,1,FALSE) -> attribute-edit | K33: Done
A34: 23 | B34: Home | My Queues | <Queue Name> | Case ### | C34: Save | D34: Button | E34: Save modified attributes | G34: No changes required | H34: http://vainpdblr15:8080/docwb/#/home/workdata/11/1001844 | I34: john | J34: =VLOOKUP(F34,lstFeatures,1,FALSE) -> #N/A | K34: Done
A35: 24 | B35: Home | My Queues | <Queue Name> | Case ### | C35: Re-Extract | D35: Button | E35: Rextract attributes on case | F35: action-create | H35: http://vainpdblr15:8080/docwb/#/home/workdata/11/1001844 | I35: john | J35: =VLOOKUP(F35,lstFeatures,1,FALSE) -> action-create | K35: Done
A36: 25 | B36: Home | My Queues | <Queue Name> | Case ### | C36: Actions | D36: Table | E36: View list of actions on case | F36: action-view | H36: http://vainpdblr15:8080/docwb/#/home/workdata/11/1001844 | I36: john | J36: =VLOOKUP(F36,lstFeatures,1,FALSE) -> action-view | K36: Done
A37: 26 | B37: Home | My Queues | <Queue Name> | Case ### | C37: Show Actions | D37: Button | E37: View list of possible actions on case | F37: action-view | H37: http://vainpdblr15:8080/docwb/#/home/workdata/11/1001844 | I37: john | J37: =VLOOKUP(F37,lstFeatures,1,FALSE) -> action-view | K37: Done
A38: 27 | B38: Home | My Queues | <Queue Name> | Case ### | Perform Action | C38: Execute | D38: Button | E38: Create new action on case | F38: action-create | H38: http://vainpdblr15:8080/docwb/#/home/workdata/11/1001844 | I38: john | J38: =VLOOKUP(F38,lstFeatures,1,FALSE) -> action-create | K38: Done
A39: 28 | B39: Home | My Queues | <Queue Name> | Case ### | C39: Case History | D39: Button | E39: View case history | F39: audit_case-view | H39: http://vainpdblr15:8080/docwb/#/home/workdata/11/1001844 | I39: john | J39: =VLOOKUP(F39,lstFeatures,1,FALSE) -> audit_case-view | K39: Done
A40: 29 | B40: Home | My Queues | <Queue Name> | Case ### | C40: Close | D40: Button | E40: Closes a case | F40: close_case-edit | H40: http://vainpdblr15:8080/docwb/#/home/worklist/11/200 | I40: john | J40: =VLOOKUP(F40,lstFeatures,1,FALSE) -> close_case-edit | K40: Done
A41: 30 | B41: Home | My Queues | <Queue Name> | Case ### | C41: Outbound Emails | D41: Table | E41: View list of outbound emails on case | F41: outbound_email-view | H41: http://vainpdblr15:8080/emailwb/#/home/workdata/3/1001358 | I41: john | J41: =VLOOKUP(F41,lstFeatures,1,FALSE) -> outbound_email-view | K41: Done
...

Sheet Data
A1: Note:
A2: The feature must be used to filter the data based on other users' role and not for logged in user's role.
A3: The feature must not be used to control the access to the API of the logged in user's role.
A5: S No. | B5: Controller | C5: API | D5: Method | E5: Description | F5: Feature
A6: 1 | B6: queue | C6: /api/v1/queue/users | D6: GET | E6: Required for a user to be eligible for being a case owner | F6: case-user-allow
A7: 2 | B7: queue | C7: /api/v1/queue/users | D7: GET | E7: Required for a user to be eligible for being a case reviewer | F7: case_review-user-allow

Sheet Service
A1: Service E.g. | B1: Engine , CaseCreator
A3: S No. | B3: Flow | C3: Capability | D3: Feature | E3: Comment | F3: Traceability | G3: Status | H3: Status-Comment
A4: 1 | C4: Get list of cases | D4: case-list | F4: =VLOOKUP(D4,lstFeatures,1,FALSE) -> case-list
A5: 2 | C5: Get list of actions across cases | D5: action-list | F5: =VLOOKUP(D5,lstFeatures,1,FALSE) -> action-list
A6: 3 | C6: View list of actions on case | D6: action-view | F6: =VLOOKUP(D6,lstFeatures,1,FALSE) -> action-view
A7: 4 | C7: View list of possible actions on case | D7: action-view | F7: =VLOOKUP(D7,lstFeatures,1,FALSE) -> action-view
A8: 5 | C8: Create new action on case | D8: action-create | F8: =VLOOKUP(D8,lstFeatures,1,FALSE) -> action-create
A9: 6 | C9: Get list of outbound emails across cases | D9: outbound_email-list | F9: =VLOOKUP(D9,lstFeatures,1,FALSE) -> outbound_email-list
A10: 7 | C10: View list of outbound emails on case | D10: outbound_email-view | F10: =VLOOKUP(D10,lstFeatures,1,FALSE) -> outbound_email-view
A11: 8 | C11: Assign case to user | D11: case-user-create | F11: =VLOOKUP(D11,lstFeatures,1,FALSE) -> case-user-create
A12: 9 | C12: View attachment(s) on case | D12: attachment-view | F12: =VLOOKUP(D12,lstFeatures,1,FALSE) -> attachment-view
A13: 10 | C13: Download attachment(s) on case | D13: attachment-view | F13: =VLOOKUP(D13,lstFeatures,1,FALSE) -> attachment-view
A14: 11 | C14: View attributes on case | D14: attribute-view | F14: =VLOOKUP(D14,lstFeatures,1,FALSE) -> attribute-view
A15: 11a | C15: View attribute source on case | D15: attribute_source-view | F15: =VLOOKUP(D15,lstFeatures,1,FALSE) -> attribute_source-view
A16: 11b | C16: View attribute annotation on case | D16: attribute_annotation-view | F16: =VLOOKUP(D16,lstFeatures,1,FALSE) -> attribute_annotation-view
A17: 11c | C17: LHS Delete attribute annotation on case | D17: attribute_annotation-delete | F17: =VLOOKUP(D17,lstFeatures,1,FALSE) -> attribute_annotation-delete
A18: 11d | C18: LHS Add attribute annotation on case | D18: attribute_annotation-create | F18: =VLOOKUP(D18,lstFeatures,1,FALSE) -> attribute_annotation-create
A19: 11e | C19: Attribute Extraction Path on case | D19: attribute_extractionpath-view | F19: =VLOOKUP(D19,lstFeatures,1,FALSE) -> attribute_extractionpath-view
A20: 12 | C20: Add new attribute on a case | D20: attribute-create | F20: =VLOOKUP(D20,lstFeatures,1,FALSE) -> attribute-create
A21: 13 | C21: Update case status | D21: case-edit | F21: =VLOOKUP(D21,lstFeatures,1,FALSE) -> case-edit
A22: 14 | C22: Closes a case | D22: close_case-edit | F22: =VLOOKUP(D22,lstFeatures,1,FALSE) -> close_case-edit
A23: 15 | C23: Add a new queue | D23: queue-create | F23: =VLOOKUP(D23,lstFeatures,1,FALSE) -> queue-create

Sheet Users
A2: Dev Environment users created for testing
A3: RoleTypeCde | B3: RoleTypeTxt | C3: Username | D3: Password
A4: 101 | B4: ADMIN | C4: docwbadmin | D4: docwbadmin
A5: 102 | B5: AGENT | C5: docwbagent | D5: docwbagent
A6: 103 | B6: MANAGER | C6: docwbmanager | D6: docwbmanager
A7: 104 | B7: GUEST | C7: docwbguest | D7: docwbguest
A8: 105 | B8: SERVICE | C8: docwbservice | D8: docwbservice

Sheet RoleMatrix-OLD
A1: Global Roles
E4: Role
A5: Module | B5: Verb | C5: Feature | D5: Feature Description | E5: admin | F5: manager | G5: agent | H5: guest | I5: service | J5: beta-user | K5: supervisor | L5: UI | M5: API
A6: core | B6: view | C6: =A6 & "-" & B6 -> core-view | D6: Mandatory features | E6: 3 | F6: 3 | G6: 3 | H6: 3
A7: core | B7: edit | C7: =A7 & "-" & B7 -> core-edit | D7: Mandatory features | E7: 3 | F7: 3 | G7: 3 | H7: 3
A8: queue | B8: list | C8: =A8 & "-" & B8 -> queue-list | D8: View queue list | E8: 3 | F8: 3 | G8: X | H8: X
A9: queue | B9: manage | C9: =A9 & "-" & B9 -> queue-manage | D9: Manage queues (assign queue to user) | E9: 3 | F9: 3 | G9: 0 or 1?
A10: queue | B10: delete | C10: =A10 & "-" & B10 -> queue-delete | D10: Delete a queue | E10: X | F10: X | J10: X | K10: X
A11: case | B11: list | C11: =A11 & "-" & B11 -> case-list | D11: View case list | E11: 3 | F11: 3 | G11: X | H11: X
A12: case | B12: assign-user | C12: =A12 & "-" & B12 -> case-assign-user | D12: Assign case to self | E12: 3 | F12: 3 | G12: 2 | H12: 0
A13: case | B13: reassign-user | C13: =A13 & "-" & B13 -> case-reassign-user | D13: Assign case to someone else | E13: 3 | F13: 3
A14: case | B14: reassign-queue | C14: =A14 & "-" & B14 -> case-reassign-queue | D14: Reassign case to queue | E14: 3 | F14: 3
A15: case | B15: close | C15: =A15 & "-" & B15 -> case-close | D15: Close case | E15: 3 | F15: 3 | G15: 2 | H15: 0
A16: case | B16: view | C16: =A16 & "-" & B16 -> case-view | D16: View case detail | E16: 3 | F16: 3 | G16: X | H16: X
A17: case | B17: create | C17: =A17 & "-" & B17 -> case-create | D17: Create case | E17: 3 | F17: 3 | G17: X | H17: X
A18: case | B18: delete | C18: =A18 & "-" & B18 -> case-delete | D18: Delete case
A19: case | B19: edit | C19: =A19 & "-" & B19 -> case-edit | D19: Edit case
A20: audit-case | B20: view | C20: =A20 & "-" & B20 -> audit-case-view | D20: View case history
A21: audit-case | B21: create | C21: =A21 & "-" & B21 -> audit-case-create | D21: Add case history
A22: audit-user | B22: view | C22: =A22 & "-" & B22 -> audit-user-view | D22: View user history
A23: attachment | B23: view | C23: =A23 & "-" & B23 -> attachment-view | D23: View document | E23: 3 | F23: 3 | G23: X | H23: X
A24: attachment | B24: create | C24: =A24 & "-" & B24 -> attachment-create | D24: Create document | E24: 3 | I24: 3
A25: outbound-email | B25: view | C25: =A25 & "-" & B25 -> outbound-email-view | D25: View outbound emails
A26: outbound-email | B26: create | C26: =A26 & "-" & B26 -> outbound-email-create | D26: Create outbound email
A27: outbound-email | B27: delete | C27: =A27 & "-" & B27 -> outbound-email-delete | D27: Delete outbound email
A28: outbound-email | B28: list | C28: =A28 & "-" & B28 -> outbound-email-list | D28: View outbound email list
A29: outbound-email | B29: edit | C29: =A29 & "-" & B29 -> outbound-email-edit | D29: Edit outbound email
A30: annotation | B30: view | C30: =A30 & "-" & B30 -> annotation-view | D30: View annotation | E30: 3 | F30: 3 | G30: X | H30: X
A31: annotation | B31: create | C31: =A31 & "-" & B31 -> annotation-create | D31: Create annotation | E31: 3 | F31: 3 | G31: X
A32: attribute | B32: view | C32: =A32 & "-" & B32 -> attribute-view | D32: View attribute | E32: 3 | F32: 3 | G32: X | H32: X
A33: attribute | B33: create | C33: =A33 & "-" & B33 -> attribute-create | D33: Create attribute | E33: 3 | F33: 3 | G33: X
A34: attribute | B34: edit | C34: =A34 & "-" & B34 -> attribute-edit | D34: Edit attribute | E34: 3 | F34: 3 | G34: X
A35: attribute | B35: delete | C35: =A35 & "-" & B35 -> attribute-delete | D35: Delete attribute | E35: 3 | F35: 3 | G35: X
A36: attribute | B36: list | C36: =A36 & "-" & B36 -> attribute-list | D36: View attributes across cases
A37: reextract | B37: create | C37: =A37 & "-" & B37 -> reextract-create | D37: Reextract attribute | E37: 3 | F37: 3 | G37: X
A38: reextract | B38: accept | C38: =A38 & "-" & B38 -> reextract-accept | D38: Accept reextract | E38: 3 | F38: 3 | G38: X
A39: action | B39: list | C39: =A39 & "-" & B39 -> action-list | D39: View action list | E39: 3 | F39: 3 | G39: X | H39: X
A40: action | B40: view | C40: =A40 & "-" & B40 -> action-view | D40: View action details | E40: 3 | F40: 3 | G40: X | H40: X
A41: action | B41: create | C41: =A41 & "-" & B41 -> action-create | D41: Create new action | E41: 3 | F41: 3 | G41: X
A42: action | B42: edit | C42: =A42 & "-" & B42 -> action-edit | D42: Edit action details
...

Sheet APIs-OLD
B1: Controller | C1: API | D1: Method | E1: Description | F1: Feature | G1: ADMIN | H1: MANAGER | I1: AGENT | J1: STATUS | K1: Comment | L1: Status
A2: 1 | B2: about | C2: /api/v1/about | D2: GET | E2: Get details about the product | F2: core-view | G2: YES | H2: YES | I2: YES | J2: Same | L2: Done
A3: 2 | B3: action | C3: /api/v1/action | D3: GET | E3: Get list of actions along with details | F3: action-list | G3: YES | H3: YES | I3: YES | J3: Same | L3: Done
C4: /api/v1/action?docId=1000742 | D4: GET | E4: Get list of actions along with details for a given docId | F4: action-view | L4: Done
B5: action | C5: /api/v1/action | D5: POST | E5: Add new action to document | F5: action-create | G5: YES | H5: YES | I5: YES | J5: Same | L5: Done
B6: action | C6: /api/v1/action | D6: PUT | E6: Update action status | F6: action-edit | G6: YES | H6: YES | I6: YES | J6: Same | L6: Done
B7: action | C7: /api/v1/action/{docActionRelId} | D7: DELETE | E7: Delete an action | F7: action-delete | G7: YES | H7: YES | I7: NO | J7: Same | L7: Done
B8: action | C8: /api/v1/action/mapping | D8: GET | E8: Returns mapping details of action's parameters with document's attributes | F8: action-view | G8: YES | H8: YES | I8: YES | J8: modified description | L8: Done
B9: action | C9: /api/v1/action/recommendation | D9: GET | E9: Get recommended action based on business rules configured | F9: action-view | G9: YES | H9: YES | I9: YES | J9: Added | L9: Done
B10: action | C10: /api/v1/action/param/attr/recommendation | D10: GET | E10: Get data for mapping details of action's parameters with document's attributes | F10: action-view | G10: YES | H10: YES | I10: YES | J10: Added | L10: Done
B11: action | C11: /api/v1/action/param/mapping | E11: Get Action Details | F11: action-view | G11: YES | H11: YES | I11: YES | J11: not found
A12: 3 | B12: attachment | C12: /api/v1/attachment/doc | D12: GET | E12: Get list of attachments associated with docId | F12: attachment-view | G12: YES | H12: YES | I12: YES | J12: Modified | L12: Done
B13: attachment | C13: /api/v1/attachment/doc | D13: POST | E13: Add a new attachment along with associated data | F13: attachment-create | G13: YES | H13: YES | I13: YES | J13: Modified | L13: Done
B14: attachment | C14: /api/v1/attachment/doc/file | D14: GET | E14: Get attachment file for a given document id & attachment id | F14: attachment-view | G14: YES | H14: YES | I14: YES | J14: Modified | L14: Done
B15: attachment | C15: /api/v1/attachment/doc/group | D15: POST | E15: Add a new attachment along with associated data to a group | F15: attachment-create | G15: YES | H15: YES | I15: YES | J15: Added | L15: Done
B16: attachment | C16: /api/v1/attachment/email | D16: GET | E16: Get list of attachments associated with email outbound id | F16: outbound-email-view | G16: YES | H16: YES | I16: YES | J16: Added | L16: Done
B17: attachment | C17: /api/v1/attachment/email/file | D17: GET | E17: Get attachment file for a given email outbound id and attachment id | F17: outbound-email-view | G17: YES | H17: YES | I17: YES | J17: Added | L17: Done
A18: 4 | B18: attribute | C18: /api/v1/attr | E18: Get list of attributes | F18: attribute-view | G18: YES | H18: YES | I18: YES | J18: not found
B19: attribute | C19: /api/v1/attr/add | E19: Add one or more attributes to a document | F19: attribute-create | G19: YES | H19: YES | I19: YES | J19: not found
B20: attribute | C20: /api/v1/attr/attrtext | E20: Get list of attributes | F20: attribute-view | G20: YES | H20: YES | I20: YES | J20: not found
B21: attribute | C21: /api/v1/attr/delete | E21: Delete an attribute | F21: attribute-delete | G21: YES | H21: YES | I21: YES | J21: not found
B22: attribute | C22: /api/v1/attr/edit | E22: Update an attribute | F22: attribute-edit | G22: YES | H22: YES | I22: YES | J22: not found
B23: attribute | C23: /api/v1/attribute/edit | D23: POST | E23: Update one or more attributes | F23: attribute-edit | G23: YES | H23: YES | I23: YES | J23: Added | L23: Done
B24: attribute | C24: /api/v1/attribute/attachment | D24: GET | E24: Get list of all (attachment) attribute(s) using docId or selected ones using [docId+attachmentId in CSV] | F24: attribute-view | G24: YES | H24: YES | I24: YES | J24: Added | L24: Done
B25: attribute | C25: /api/v1/attribute/values | D25: GET | E25: Get list of allowed value(s) for attribute(s), if configured | F25: attribute-view | G25: YES | H25: YES | I25: YES | J25: Added | L25: Done
B26: attribute | C26: /api/v1/attribute/notification | D26: GET | E26: Get notifications for attribute(s) based on business rules configured | F26: attribute-view | G26: YES | H26: YES | I26: YES | J26: Added | L26: Done
B27: attribute | C27: /api/v1/attribute/export | D27: GET | E27: Export list of all (document and attachment) attributes | F27: attribute-list | G27: YES | H27: YES | I27: YES | J27: Added | L27: Done
B28: attribute | C28: /api/v1/attribute/document | D28: GET | E28: Get list of all (document) attributes | F28: attribute-view | G28: YES | H28: YES | I28: YES | J28: Added | L28: Done
B29: attribute | C29: /api/v1/attribute/sortkey | D29: GET | E29: Get sort key for attributes | F29: attribute-view | G29: YES | H29: YES | I29: YES | J29: Added | L29: Done
B30: attribute | C30: /api/v1/attribute/attribute/mapping | D30: GET | E30: Get list of all attribute-to-attribute mapping | F30: attribute-view | G30: YES | H30: YES | I30: YES | J30: Added | L30: Done
B31: attribute | C31: /api/v1/attribute/names | D31: GET | E31: Get list of all attribute name(s), if configured | F31: attribute-view | G31: YES | H31: YES | I31: YES | J31: Added | L31: Done
B32: attribute | C32: /api/v1/attribute/delete | D32: POST | E32: Delete one or more attributes | F32: attribute-delete | G32: YES | H32: YES | I32: YES | J32: Added | L32: Done
B33: attribute | C33: /api/v1/attribute/add | D33: POST | E33: Add one or more attributes | F33: attribute-create | G33: YES | H33: YES | I33: YES | J33: Added | L33: Done
B34: annotation | C34: /api/v1/annotation/add | D34: POST | E34: Add one or more annotations | F34: attribute-create | G34: YES | H34: YES | I34: YES | J34: Added | L34: Done
... B36: multiattribute | C36: /api/v1/multiattribute/manage | D36: POST | E36: Add/update/delete multi-attribute at document/attachment level | F36: attribute-create | G36: YES | H36: YES | I36: YES | J36: Added | L36: Done
C37: /api/v1/multiattribute/manage | D37: POST | E37: Add/update/delete multi-attribute at document/attachment level | F37: attribute-edit
C38: /api/v1/multiattribute/manage | D38: POST | E38: Add/update/delete multi-attribute at document/attachment level | F38: attribute-delete
B39: audit | C39: /api/v1/audit/document | D39: GET | E39: Get audit details | F39: audit-case-view | G39: YES | H39: YES | I39: YES | J39: Added | L39: Done
B40: audit | C40: /api/v1/audit/document | D40: POST | E40: Add audit details at case level | F40: audit-case-create | G40: YES | H40: YES | I40: YES | J40: Added | L40: Done
B41: audit | C41: /api/v1/audit/user | D41: GET | E41: Get audit details | F41: audit-user-view | G41: YES | H41: YES | I41: NO | J41: Added | L41: Done
...

Sheet UI-OLD
B1: # | C1: Web page URL | D1: User | E1: Capability | F1: Feature
B2: 1 | C2: http://vainpdblr15:8080/docwb/#/home/myqueues | D2: john | E2: View queues | F2: queue-list
C3: http://vainpdblr15:8080/docwb/#/home/worklist/11/100 | D3: john | E3: View list of cases | F3: case-list
C4: http://vainpdblr15:8080/docwb/#/home/workdata/11/1014334 | D4: john | E4: View case detail | F4: case-view
C5: http://vainpdblr15:8080/docwb/#/home/worklist/11/200 | D5: john | E5: View list of cases in progress | F5: case-list
C6: http://vainpdblr15:8080/docwb/#/home/worklist/11/200 | D6: john | E6: Closes a case | F6: case-close
C7: http://vainpdblr15:8080/docwb/#/home/worklist/11/200 | D7: john | E7: Assign case to someone else | F7: case-reassign-user
C8: http://vainpdblr15:8080/docwb/#/home/worklist/11/200 | D8: john | E8: View cases assigned to self | F8: case-view
C9: http://vainpdblr15:8080/docwb/#/home/worklist/11/100 | D9: john | E9: Assign case to self from unassigned in NEW | F9: case-assign-user
C10: http://vainpdblr15:8080/docwb/#/home/workdata/11/1001844 | D10: john | E10: View attribute | F10: attribute-view
C11: http://vainpdblr15:8080/docwb/#/home/workdata/11/1001845 | D11: john | E11: View action list | F11: action-list
C12: http://vainpdblr15:8080/docwb/#/home/workdata/11/1001844 | D12: john | E12: View case history | F12: case-history
C13: http://vainpdblr15:8080/docwb/#/home/workdata/11/1001861 | D13: john | E13: Create attribute | F13: attribute-create
C14: http://vainpdblr15:8080/docwb/#/home/workdata/11/1001862 | D14: john | E14: Delete attribute | F14: attribute-delete
... C20: http://vainpdblr15:8080/docwb/#/home/admin/userlist | D20: Admin | E20: specific queue access can be provided/removed | F20: user-manage
